<?xml version="1.0" encoding="utf-8"?>
<robot
  name="e05_pro" xmlns:xacro="http://www.ros.org/wiki/xacro">

  <link name="world"/>
  <joint name="fixed_base" type="fixed">
    <parent link="world"/>
    <child link="base_link"/>
    <origin xyz="0 0 0" rpy="0 0 0"/>
  </joint>

  <link
    name="base_link">
    <inertial>
      <origin
        xyz="-5.8308E-06 -0.00076389 0.029442"
        rpy="0 0 0" />
      <mass
        value="0.97024" />
      <inertia
        ixx="0.0014457"
        ixy="-1.1433E-07"
        ixz="6.8575E-08"
        iyy="0.001577"
        iyz="-2.1682E-05"
        izz="0.0023657" />
    </inertial>
    <visual>
      <origin
        xyz="0 0 0"
        rpy="0 0 0" />
      <geometry>
        <mesh
          filename="file://$(find e05_pro)/meshes/visual/base_link.STL" />
      </geometry>
      <material
        name="">
        <color
          rgba="0.79216 0.81961 0.92941 1" />
      </material>
    </visual>
    <collision>
      <origin
        xyz="0 0 0"
        rpy="0 0 0" />
      <geometry>
        <mesh
          filename="file://$(find e05_pro)/meshes/collision/base_link.STL" />
      </geometry>
    </collision>
  </link>
  <link
    name="link1">
    <inertial>
      <origin
        xyz="0.0059053 2.7648E-06 0.10841"
        rpy="0 0 0" />
      <mass
        value="3.1639" />
      <inertia
        ixx="0.012143"
        ixy="-1.1966E-07"
        ixz="-0.0023646"
        iyy="0.012964"
        iyz="4.1909E-07"
        izz="0.0069485" />
    </inertial>
    <visual>
      <origin
        xyz="0 0 0"
        rpy="0 0 0" />
      <geometry>
        <mesh
          filename="file://$(find e05_pro)/meshes/visual/link1.STL" />
      </geometry>
      <material
        name="">
        <color
          rgba="1 1 1 1" />
      </material>
    </visual>
    <collision>
      <origin
        xyz="0 0 0"
        rpy="0 0 0" />
      <geometry>
        <mesh
          filename="file://$(find e05_pro)/meshes/collision/link1.STL" />
      </geometry>
    </collision>
  </link>
  <joint
    name="joint1"
    type="revolute">
    <origin
      xyz="0 0 0.0735"
      rpy="0 0 0" />
    <parent
      link="base_link" />
    <child
      link="link1" />
    <axis
      xyz="0 0 -1" />
    <limit
      lower="-3.14"
      upper="3.14"
      effort="250"
      velocity="1" />
  </joint>
  <link
    name="link2">
    <inertial>
      <origin
        xyz="0.042176 -3.9101E-06 0.15918"
        rpy="0 0 0" />
      <mass
        value="2.8026" />
      <inertia
        ixx="0.047876"
        ixy="2.9287E-07"
        ixz="0.0015426"
        iyy="0.047201"
        iyz="-3.7973E-06"
        izz="0.0027945" />
    </inertial>
    <visual>
      <origin
        xyz="0 0 0"
        rpy="0 0 0" />
      <geometry>
        <mesh
          filename="file://$(find e05_pro)/meshes/visual/link2.STL" />
      </geometry>
      <material
        name="">
        <color
          rgba="0.89804 0.91373 0.92549 1" />
      </material>
    </visual>
    <collision>
      <origin
        xyz="0 0 0"
        rpy="0 0 0" />
      <geometry>
        <mesh
          filename="file://$(find e05_pro)/meshes/collision/link2.STL" />
      </geometry>
    </collision>
  </link>
  <joint
    name="joint2"
    type="revolute">
    <origin
      xyz="0.0855 0 0.1455"
      rpy="0 0 0" />
    <parent
      link="link1" />
    <child
      link="link2" />
    <axis
      xyz="1 0 0" />
    <limit
      lower="-3.14"
      upper="3.14"
      effort="250"
      velocity="1" />
  </joint>
  <link
    name="link3">
    <inertial>
      <origin
        xyz="-0.072868 8.9155E-06 0.030313"
        rpy="0 0 0" />
      <mass
        value="1.9252" />
      <inertia
        ixx="0.0051727"
        ixy="-7.3729E-07"
        ixz="0.0011237"
        iyy="0.0058722"
        iyz="-2.7991E-07"
        izz="0.0031696" />
    </inertial>
    <visual>
      <origin
        xyz="0 0 0"
        rpy="0 0 0" />
      <geometry>
        <mesh
          filename="file://$(find e05_pro)/meshes/visual/link3.STL" />
      </geometry>
      <material
        name="">
        <color
          rgba="0.65098 0.61961 0.58431 1" />
      </material>
    </visual>
    <collision>
      <origin
        xyz="0 0 0"
        rpy="0 0 0" />
      <geometry>
        <mesh
          filename="file://$(find e05_pro)/meshes/collision/link3.STL" />
      </geometry>
    </collision>
  </link>
  <joint
    name="joint3"
    type="revolute">
    <origin
      xyz="-0.007 0 0.38"
      rpy="0 0 0" />
    <parent
      link="link2" />
    <child
      link="link3" />
    <axis
      xyz="-1 0 0" />
    <limit
      lower="-3.14"
      upper="3.14"
      effort="250"
      velocity="1" />
  </joint>
  <link
    name="link4">
    <inertial>
      <origin
        xyz="0.059247 -3.3739E-05 0.12471"
        rpy="0 0 0" />
      <mass
        value="1.3967" />
      <inertia
        ixx="0.012839"
        ixy="1.7257E-06"
        ixz="-0.0038561"
        iyy="0.014642"
        iyz="6.2767E-06"
        izz="0.0031137" />
    </inertial>
    <visual>
      <origin
        xyz="0 0 0"
        rpy="0 0 0" />
      <geometry>
        <mesh
          filename="file://$(find e05_pro)/meshes/visual/link4.STL" />
      </geometry>
      <material
        name="white">
        <color
          rgba="1 1 1 1" />
      </material>
    </visual>
    <collision>
      <origin
        xyz="0 0 0"
        rpy="0 0 0" />
      <geometry>
        <mesh
          filename="file://$(find e05_pro)/meshes/collision/link4.STL" />
      </geometry>
    </collision>
  </link>
  <joint
    name="joint4"
    type="revolute">
    <origin
      xyz="-0.0785 0 0.124"
      rpy="0 0 0" />
    <parent
      link="link3" />
    <child
      link="link4" />
    <axis
      xyz="0 0 1" />
    <limit
      lower="-3.14"
      upper="3.14"
      effort="250"
      velocity="1" />
  </joint>
  <link
    name="link5">
    <inertial>
      <origin
        xyz="-0.0612 -4.6645E-07 0.022517"
        rpy="0 0 0" />
      <mass
        value="0.99024" />
      <inertia
        ixx="0.0016081"
        ixy="-9.4466E-08"
        ixz="0.00037479"
        iyy="0.001931"
        iyz="-3.9653E-08"
        izz="0.0010972" />
    </inertial>
    <visual>
      <origin
        xyz="0 0 0"
        rpy="0 0 0" />
      <geometry>
        <mesh
          filename="file://$(find e05_pro)/meshes/visual/link5.STL" />
      </geometry>
      <material
        name="white">
        <color
          rgba="1 1 1 1" />
      </material>
    </visual>
    <collision>
      <origin
        xyz="0 0 0"
        rpy="0 0 0" />
      <geometry>
        <mesh
          filename="file://$(find e05_pro)/meshes/collision/link5.STL" />
      </geometry>
    </collision>
  </link>
  <joint
    name="joint5"
    type="revolute">
    <origin
      xyz="0.0655 0 0.296"
      rpy="0 0 0" />
    <parent
      link="link4" />
    <child
      link="link5" />
    <axis
      xyz="1 0 0" />
    <limit
      lower="-3.14"
      upper="3.14"
      effort="250"
      velocity="1" />
  </joint>
  <link
    name="link6">
    <inertial>
      <origin
        xyz="0.00014734 -6.0589E-07 0.039571"
        rpy="0 0 0" />
      <mass
        value="0.38809" />
      <inertia
        ixx="0.00032092"
        ixy="1.1678E-07"
        ixz="-9.261E-07"
        iyy="0.0003233"
        iyz="9.15E-08"
        izz="0.00036139" />
    </inertial>
    <visual>
      <origin
        xyz="0 0 0"
        rpy="0 0 0" />
      <geometry>
        <mesh
          filename="file://$(find e05_pro)/meshes/visual/link6.STL" />
      </geometry>
      <material
        name="white">
        <color
          rgba="1 1 1 1" />
      </material>
    </visual>
    <collision>
      <origin
        xyz="0 0 0"
        rpy="0 0 0" />
      <geometry>
        <mesh
          filename="file://$(find e05_pro)/meshes/collision/link6.STL" />
      </geometry>
    </collision>
  </link>
  <joint
    name="joint6"
    type="revolute">
    <origin
      xyz="-0.0655 0 0.098184"
      rpy="0 0 0" />
    <parent
      link="link5" />
    <child
      link="link6" />
    <axis
      xyz="0 0 -1" />
    <limit
      lower="-3.14"
      upper="3.14"
      effort="250"
      velocity="1" />
  </joint>

  <link name="robotiq_link">
    <visual>
      <origin xyz="0 0 0" rpy="0 0 0" />
      <geometry>
        <sphere radius="0.01" /> 
      </geometry>
      <material name="">
        <color rgba="1 0 0 1" /> 
      </material>
    </visual>
  </link>

  <joint name="robotiq_joint" type="fixed">
    <origin xyz="0 0 0.070" rpy="0 0 0" />
    <parent link="link6" />
    <child link="robotiq_link" />
  </joint>
</robot>